<?xml version="1.0"?>
<robot xmlns:xacro="http://www.ros.org/wiki/xacro" name="jetbot_mirea">

    <xacro:include filename="common_properties.xacro"/>

    <link name="base_footprint"/>
    
    <joint name="base_joint" type="fixed">
        <parent link="base_footprint"/>
        <child link="base_link"/>
        <origin xyz="0.0 0.0 0.0" rpy="0 0 0"/>
    </joint>

    <link name="base_link">
        <visual>
            <origin xyz="0.0 0.0 0.0" rpy="0 0 0"/>
            <geometry>
                <box size="0.132 0.095 0.032"/>
            </geometry>
            <material name="acid_green"/>
        </visual>

        <collision>
            <origin xyz="0.0 0.0 0.0" rpy="0 0 0"/>
            <geometry>
                <box size="0.132 0.095 0.032"/>
            </geometry>
        </collision>

        <xacro:inertial_box mass="0.005" x="0.132" y="0.095" z="0.032">
            <origin xyz="0.0 0.0 0.0" rpy="0 0 0"/>
        </xacro:inertial_box>
        
    </link>

    <joint name="wheel_left_joint" type="continuous">
        <parent link="base_link"/>
        <child link="wheel_left_link"/>
        <origin xyz="0.0 -0.06 -0.005" rpy="-1.57 0 0"/>
        <axis xyz="0 0 1"/>
    </joint>

    <link name="wheel_left_link">
        <visual>
            <origin xyz="0 -0.06 -0.005" rpy="1.57 0 0"/>
            <geometry>
                <cylinder length="0.029" radius="0.032"/>
            </geometry>
            <material name="dark"/>
        </visual>

        <collision>
            <origin xyz="0 -0.06 -0.005" rpy="0 0 0"/>
            <geometry>
                <cylinder length="0.029" radius="0.032"/>
            </geometry>
        </collision>

        <xacro:inertial_cylinder mass="0.001" length="0.029" radius="0.032">
            <origin xyz="0.0 -0.06 -0.005" rpy="0.0 0.0 0.0"/>
        </xacro:inertial_cylinder>

    </link>

    <joint name="wheel_right_joint" type="continuous">
        <parent link="base_link"/>
        <child link="wheel_right_link"/>
        <origin xyz="0 0.06 -0.005" rpy="0 0 0"/>
        <axis xyz="0 0 1"/>
    </joint>

    <link name="wheel_right_link">
        <visual>
            <origin xyz="0 0.06 -0.005" rpy="-1.57 0 0"/>
            <geometry>
                <cylinder length="0.029" radius="0.032"/>
            </geometry>
            <material name="dark"/>
        </visual>
       
        <collision>
            <origin xyz="0 0.06 -0.005" rpy="1.57 0 0"/>
            <geometry>
                <cylinder length="0.029" radius="0.032"/>
            </geometry>
        </collision>
        
        <xacro:inertial_cylinder mass="0.0010" length="0.029" radius="0.032">
            <origin xyz="0 0.06 -0.005" rpy="0 0 0"/>
        </xacro:inertial_cylinder>
    </link>
</robot>